<?xml version="1.0"?><robot name="pepe">
	<link name="0">
		<visual>
			<geometry>
				<cylinder length="1.7473303517172418" radius="0.11150932087712773"/>
			</geometry>
		</visual>
		<collision>
			<geometry>
				<cylinder length="1.7473303517172418" radius="0.11150932087712773"/>
			</geometry>
		</collision>
		<inertial>
			<mass value="0.06825700609149243"/>
			<inertia ixx="0.03" iyy="0.03" izz="0.03" ixy="0" ixz="0" iyx="0"/>
		</inertial>
	</link>
	<link name="11">
		<visual>
			<geometry>
				<cylinder length="0.8212600839258406" radius="0.899494169212198"/>
			</geometry>
		</visual>
		<collision>
			<geometry>
				<cylinder length="0.8212600839258406" radius="0.899494169212198"/>
			</geometry>
		</collision>
		<inertial>
			<mass value="2.0875038866507785"/>
			<inertia ixx="0.03" iyy="0.03" izz="0.03" ixy="0" ixz="0" iyx="0"/>
		</inertial>
	</link>
	<link name="22">
		<visual>
			<geometry>
				<cylinder length="0.8830953853196264" radius="0.2370516937341821"/>
			</geometry>
		</visual>
		<collision>
			<geometry>
				<cylinder length="0.8830953853196264" radius="0.2370516937341821"/>
			</geometry>
		</collision>
		<inertial>
			<mass value="0.1558991019377649"/>
			<inertia ixx="0.03" iyy="0.03" izz="0.03" ixy="0" ixz="0" iyx="0"/>
		</inertial>
	</link>
	<link name="23">
		<visual>
			<geometry>
				<cylinder length="0.8830953853196264" radius="0.2370516937341821"/>
			</geometry>
		</visual>
		<collision>
			<geometry>
				<cylinder length="0.8830953853196264" radius="0.2370516937341821"/>
			</geometry>
		</collision>
		<inertial>
			<mass value="0.1558991019377649"/>
			<inertia ixx="0.03" iyy="0.03" izz="0.03" ixy="0" ixz="0" iyx="0"/>
		</inertial>
	</link>
	<link name="24">
		<visual>
			<geometry>
				<cylinder length="0.8830953853196264" radius="0.2370516937341821"/>
			</geometry>
		</visual>
		<collision>
			<geometry>
				<cylinder length="0.8830953853196264" radius="0.2370516937341821"/>
			</geometry>
		</collision>
		<inertial>
			<mass value="0.1558991019377649"/>
			<inertia ixx="0.03" iyy="0.03" izz="0.03" ixy="0" ixz="0" iyx="0"/>
		</inertial>
	</link>
	<link name="15">
		<visual>
			<geometry>
				<cylinder length="0.8212600839258406" radius="0.899494169212198"/>
			</geometry>
		</visual>
		<collision>
			<geometry>
				<cylinder length="0.8212600839258406" radius="0.899494169212198"/>
			</geometry>
		</collision>
		<inertial>
			<mass value="2.0875038866507785"/>
			<inertia ixx="0.03" iyy="0.03" izz="0.03" ixy="0" ixz="0" iyx="0"/>
		</inertial>
	</link>
	<link name="26">
		<visual>
			<geometry>
				<cylinder length="0.8830953853196264" radius="0.2370516937341821"/>
			</geometry>
		</visual>
		<collision>
			<geometry>
				<cylinder length="0.8830953853196264" radius="0.2370516937341821"/>
			</geometry>
		</collision>
		<inertial>
			<mass value="0.1558991019377649"/>
			<inertia ixx="0.03" iyy="0.03" izz="0.03" ixy="0" ixz="0" iyx="0"/>
		</inertial>
	</link>
	<link name="27">
		<visual>
			<geometry>
				<cylinder length="0.8830953853196264" radius="0.2370516937341821"/>
			</geometry>
		</visual>
		<collision>
			<geometry>
				<cylinder length="0.8830953853196264" radius="0.2370516937341821"/>
			</geometry>
		</collision>
		<inertial>
			<mass value="0.1558991019377649"/>
			<inertia ixx="0.03" iyy="0.03" izz="0.03" ixy="0" ixz="0" iyx="0"/>
		</inertial>
	</link>
	<link name="28">
		<visual>
			<geometry>
				<cylinder length="0.8830953853196264" radius="0.2370516937341821"/>
			</geometry>
		</visual>
		<collision>
			<geometry>
				<cylinder length="0.8830953853196264" radius="0.2370516937341821"/>
			</geometry>
		</collision>
		<inertial>
			<mass value="0.1558991019377649"/>
			<inertia ixx="0.03" iyy="0.03" izz="0.03" ixy="0" ixz="0" iyx="0"/>
		</inertial>
	</link>
	<joint name="11_to_0" type="revolute">
		<parent link="0"/>
		<child link="11"/>
		<axis xyz="1 0 0"/>
		<limit effort="1" upper="-3.1415" lower="3.1415" velocity="1"/>
		<origin rpy="0.7279228957594582 3.4874446088140054 2.6294261494538747" xyz="0.3980061349550241 0.7055798917446608 0.27126572159245044"/>
	</joint>
	<joint name="22_to_11" type="revolute">
		<parent link="11"/>
		<child link="22"/>
		<axis xyz="1 0 0"/>
		<limit effort="1" upper="-3.1415" lower="3.1415" velocity="1"/>
		<origin rpy="0.6539193366907576 1.7753182757952812 3.759150098475003" xyz="0.7496341351539453 0.43383752768269634 0.5254019843342813"/>
	</joint>
	<joint name="23_to_11" type="revolute">
		<parent link="11"/>
		<child link="23"/>
		<axis xyz="1 0 0"/>
		<limit effort="1" upper="-3.1415" lower="3.1415" velocity="1"/>
		<origin rpy="0.9808790050361365 1.7753182757952812 3.759150098475003" xyz="0.7496341351539453 0.43383752768269634 0.5254019843342813"/>
	</joint>
	<joint name="24_to_11" type="revolute">
		<parent link="11"/>
		<child link="24"/>
		<axis xyz="1 0 0"/>
		<limit effort="1" upper="-3.1415" lower="3.1415" velocity="1"/>
		<origin rpy="1.3078386733815153 1.7753182757952812 3.759150098475003" xyz="0.7496341351539453 0.43383752768269634 0.5254019843342813"/>
	</joint>
	<joint name="15_to_0" type="revolute">
		<parent link="0"/>
		<child link="15"/>
		<axis xyz="1 0 0"/>
		<limit effort="1" upper="-3.1415" lower="3.1415" velocity="1"/>
		<origin rpy="1.0918843436391874 3.4874446088140054 2.6294261494538747" xyz="0.3980061349550241 0.7055798917446608 0.27126572159245044"/>
	</joint>
	<joint name="26_to_15" type="revolute">
		<parent link="15"/>
		<child link="26"/>
		<axis xyz="1 0 0"/>
		<limit effort="1" upper="-3.1415" lower="3.1415" velocity="1"/>
		<origin rpy="0.6539193366907576 1.7753182757952812 3.759150098475003" xyz="0.7496341351539453 0.43383752768269634 0.5254019843342813"/>
	</joint>
	<joint name="27_to_15" type="revolute">
		<parent link="15"/>
		<child link="27"/>
		<axis xyz="1 0 0"/>
		<limit effort="1" upper="-3.1415" lower="3.1415" velocity="1"/>
		<origin rpy="0.9808790050361365 1.7753182757952812 3.759150098475003" xyz="0.7496341351539453 0.43383752768269634 0.5254019843342813"/>
	</joint>
	<joint name="28_to_15" type="revolute">
		<parent link="15"/>
		<child link="28"/>
		<axis xyz="1 0 0"/>
		<limit effort="1" upper="-3.1415" lower="3.1415" velocity="1"/>
		<origin rpy="1.3078386733815153 1.7753182757952812 3.759150098475003" xyz="0.7496341351539453 0.43383752768269634 0.5254019843342813"/>
	</joint>
</robot>
